<?xml version="1.0"?>
<robot name="wheel" xmlns:xacro="http://www.ros.org/wiki/xacro">

  <xacro:property name="PI" value="3.1415926535897931" />

  <!-- Wheels -->
  <xacro:property name="wheel_radius" value="0.127" />
  <xacro:property name="wheel_height" value="0.087" />
  <xacro:property name="wheel_mass" value="6.5" /> <!-- in kg-->

 

<!-- 
	=================== OMNI_WHEEL ==========================
-->
  <xacro:macro name="omni_wheel" params="prefix parent *origin reflect">

    <joint name="${prefix}_wheel_joint" type="continuous">
      <parent link="${parent}"/>
      <child link="${prefix}_wheel_link"/>
      <xacro:insert_block name="origin" />
      <axis xyz="0 1 0" rpy="0 0 0" />
      <limit effort="2000" velocity="100"/>
      <joint_properties damping="0.01" friction="1000.0"/>
    </joint>

    <transmission name="${prefix}_wheel_transmission">
      <type>transmission_interface/SimpleTransmission</type>
      <joint name="${prefix}_wheel_joint">
        <hardwareInterface>hardware_interface/EffortJointInterface</hardwareInterface>
      </joint>
      <actuator name="${prefix}_wheel_actuator">
        <mechanicalReduction>1</mechanicalReduction>
        <hardwareInterface>EffortJointInterface</hardwareInterface>
      </actuator>
    </transmission>

    <link name="${prefix}_wheel_link">

      <visual>
        <origin xyz="0 0 0" rpy="0 0 0" />
        <xacro:if value="${reflect}">
          <geometry>
            <mesh filename="package://stage_description/meshes/wheels/omni_wheel_1.dae" scale="0.6 0.6 0.6"/>
          </geometry>
          <surface>
            <friction>
              <ode>
                <mu>10000.0</mu>
                <mu2>10000.0</mu2>
              </ode>
            </friction>
            <contact>
              <ode>
                <min_depth>0.003</min_depth>
              </ode>
            </contact>
          </surface>
        </xacro:if>

        <xacro:unless value="${reflect}">
            <geometry>
              <mesh filename="package://stage_description/meshes/wheels/omni_wheel_2.dae" scale="0.6 0.6 0.6"/>
            </geometry>
            <surface>
              <friction>
                <ode>
                  <mu>1000.0</mu>
                  <mu2>1000.0</mu2>
                  <kp>10000.0</kp>
                  <kd>100.0</kd> r
                </ode>
              </friction>
              <contact>
                <ode>
                  <min_depth>0.1</min_depth>
                </ode>
              </contact>
            </surface>
		 </xacro:unless>
      </visual> 

	  <inertial>
       	<mass value="${wheel_mass}" />
       	<origin xyz="0 0 0" />
       	<inertia  ixx="0.0000003" ixy = "0" ixz = "0"    iyy="0.00000003" iyz = "0" izz="0.00000003" /> 
        <!--ixx="0.0303095" ixy = "0" ixz = "0"    iyy="0.052419" iyz = "0" izz="0.0303095"-->
      </inertial>

    </link>

    <!-- Transmission is important to link the joints and the controller (see stage_control/control/mybot_control.yaml)-->
    <transmission name="${prefix}_wheel_joint_trans">
      <type>transmission_interface/SimpleTransmission</type>
      <joint name="${prefix}_wheel_joint" >
        <hardwareInterface>hardware_interface/EffortJointInterface</hardwareInterface>
      </joint>
      <actuator name="${prefix}_wheel_joint_motor">
         <mechanicalReduction>1</mechanicalReduction>
      </actuator>
    </transmission>
	
	<!-- friction -->
    <gazebo reference="${prefix}_wheel_link">
		  <selfCollide>true</selfCollide>
      <dynamics damping="0.01" friction="1000.0"/>
      <mu1 value="10000.0" />
      <mu2 value="100.2" />
		  <fdir1 value="1 0 0"/>
      <kp>1000.0</kp>
      <kd>10.0</kd>
      <turnGravityOff>false</turnGravityOff>
    </gazebo>
	
  </xacro:macro>	

</robot>

